Workbook

Sheet Q2-Dice
A1: Simulate a game of dice that generates discrete random variate using random number generation
C3: Player
C4: A | D4: B | E4: C
A5: Iteration | B5: 1 | C5: =RANDBETWEEN(1,6) -> 6 | D5: =RANDBETWEEN(1,6) -> 2 | E5: =RANDBETWEEN(1,6) -> 3
B6: 2 | C6: =RANDBETWEEN(1,6) -> 6 | D6: =RANDBETWEEN(1,6) -> 3 | E6: =RANDBETWEEN(1,6) -> 1
B7: 3 | C7: =RANDBETWEEN(1,6) -> 1 | D7: =RANDBETWEEN(1,6) -> 3 | E7: =RANDBETWEEN(1,6) -> 3
B8: 4 | C8: =RANDBETWEEN(1,6) -> 6 | D8: =RANDBETWEEN(1,6) -> 5 | E8: =RANDBETWEEN(1,6) -> 2
B9: 5 | C9: =RANDBETWEEN(1,6) -> 5 | D9: =RANDBETWEEN(1,6) -> 4 | E9: =RANDBETWEEN(1,6) -> 6

Sheet Q3-SingleServerQueueSim
A1: Simulate a performance evaluation of single server queuing system.
A2: Assuming the following scenario for a single server queuing system for simulation of 6 customer, with inter arrival time from 1-6 mins
A4: Service Time(min) | B4: 1 | C4: 2 | D4: 3 | E4: 4 | F4: 5 | G4: 6
A5: Probability | B5: 0.1 | C5: 0.2 | D5: 0.3 | E5: 0.25 | F5: 0.1 | G5: 0.05
A7: RandomDigits(For Arrival) | B7: - | C7: 913 | D7: 727 | E7: 15 | F7: 948 | G7: 309
A8: RandomDigits(For Service) | B8: 84 | C8: 10 | D8: 74 | E8: 53 | F8: 17 | G8: 79
C11: Arrival Time Distribution | I11: Service Time Distribution
B12: Inter-Arrival Time | C12: Probability Of Event | D12: Cumulative Probability | E12: Random Digit FROM | F12: Random Digit TO | H12: Service Time | I12: Probability | J12: Cumulative Probability | K12: Random Digit FROM | L12: Random Digit TO
B13: 1 | C13: =1/$B$20 -> 0.125 | D13: =SUM($C$13:C13) -> 0.125 | E13: 1 | F13: =ArrivalDistribution[[#This Row],[Cumulative Probability]]*1000 -> 125 | H13: 1 | I13: 0.1 | J13: =SUM($I$13:I13) -> 0.1 | K13: 1 | L13: =ServiceDistribution3[[#This Row],[Cumulative Probability]]*100 -> 10
B14: 2 | C14: =1/$B$20 -> 0.125 | D14: =SUM($C$13:C14) -> 0.25 | E14: =F13+1 -> 126 | F14: =ArrivalDistribution[[#This Row],[Cumulative Probability]]*1000 -> 250 | H14: 2 | I14: 0.2 | J14: =SUM($I$13:I14) -> 0.3 | K14: =L13+1 -> 11 | L14: =ServiceDistribution3[[#This Row],[Cumulative Probability]]*100 -> 30
B15: 3 | C15: =1/$B$20 -> 0.125 | D15: =SUM($C$13:C15) -> 0.375 | E15: =F14+1 -> 251 | F15: =ArrivalDistribution[[#This Row],[Cumulative Probability]]*1000 -> 375 | H15: 3 | I15: 0.3 | J15: =SUM($I$13:I15) -> 0.6 | K15: =L14+1 -> 31 | L15: =ServiceDistribution3[[#This Row],[Cumulative Probability]]*100 -> 60
B16: 4 | C16: =1/$B$20 -> 0.125 | D16: =SUM($C$13:C16) -> 0.5 | E16: =F15+1 -> 376 | F16: =ArrivalDistribution[[#This Row],[Cumulative Probability]]*1000 -> 500 | H16: 4 | I16: 0.25 | J16: =SUM($I$13:I16) -> 0.85 | K16: =L15+1 -> 61 | L16: =ServiceDistribution3[[#This Row],[Cumulative Probability]]*100 -> 85
B17: 5 | C17: =1/$B$20 -> 0.125 | D17: =SUM($C$13:C17) -> 0.625 | E17: =F16+1 -> 501 | F17: =ArrivalDistribution[[#This Row],[Cumulative Probability]]*1000 -> 625 | H17: 5 | I17: 0.1 | J17: =SUM($I$13:I17) -> 0.95 | K17: =L16+1 -> 86 | L17: =ServiceDistribution3[[#This Row],[Cumulative Probability]]*100 -> 95
B18: 6 | C18: =1/$B$20 -> 0.125 | D18: =SUM($C$13:C18) -> 0.75 | E18: =F17+1 -> 626 | F18: =ArrivalDistribution[[#This Row],[Cumulative Probability]]*1000 -> 750 | H18: 6 | I18: 0.05 | J18: =SUM($I$13:I18) -> 1 | K18: =L17+1 -> 96 | L18: 99
B19: 7 | C19: =1/$B$20 -> 0.125 | D19: =SUM($C$13:C19) -> 0.875 | E19: =F18+1 -> 751 | F19: =ArrivalDistribution[[#This Row],[Cumulative Probability]]*1000 -> 875
B20: 8 | C20: =1/$B$20 -> 0.125 | D20: =SUM($C$13:C20) -> 1 | E20: =F19+1 -> 876 | F20: 999
C23: Arrival Time Assignment | I23: Service Time Assignment
C24: Customer | D24: RandomDigit | E24: Selected Arrival Time | I24: Customer | J24: RandomDigit | K24: Selected Service Time
C25: 1 | I25: 1 | J25: =RANDBETWEEN($K$13,$L$18) -> 46 | K25: =INDEX(ServiceDistribution3[Service Time], MATCH(ServiceTimeAssignment[[#This Row],[RandomDigit]], ServiceDistribution3[Random Digit FROM], 1)) -> 3
C26: 2 | D26: =RANDBETWEEN($E$13,$F$20) -> 698 | E26: =INDEX(ArrivalDistribution[Inter-Arrival Time], MATCH(ArrivalAssignment[[#This Row],[RandomDigit]], ArrivalDistribution[Random Digit FROM], 1)) -> 6 | I26: 2 | J26: =RANDBETWEEN($K$13,$L$18) -> 52 | K26: =INDEX(ServiceDistribution3[Service Time], MATCH(ServiceTimeAssignment[[#This Row],[RandomDigit]], ServiceDistribution3[Random Digit FROM], 1)) -> 3
C27: 3 | D27: =RANDBETWEEN($E$13,$F$20) -> 409 | E27: =INDEX(ArrivalDistribution[Inter-Arrival Time], MATCH(ArrivalAssignment[[#This Row],[RandomDigit]], ArrivalDistribution[Random Digit FROM], 1)) -> 4 | I27: 3 | J27: =RANDBETWEEN($K$13,$L$18) -> 26 | K27: =INDEX(ServiceDistribution3[Service Time], MATCH(ServiceTimeAssignment[[#This Row],[RandomDigit]], ServiceDistribution3[Random Digit FROM], 1)) -> 2
C28: 4 | D28: =RANDBETWEEN($E$13,$F$20) -> 417 | E28: =INDEX(ArrivalDistribution[Inter-Arrival Time], MATCH(ArrivalAssignment[[#This Row],[RandomDigit]], ArrivalDistribution[Random Digit FROM], 1)) -> 4 | I28: 4 | J28: =RANDBETWEEN($K$13,$L$18) -> 54 | K28: =INDEX(ServiceDistribution3[Service Time], MATCH(ServiceTimeAssignment[[#This Row],[RandomDigit]], ServiceDistribution3[Random Digit FROM], 1)) -> 3
C29: 5 | D29: =RANDBETWEEN($E$13,$F$20) -> 313 | E29: =INDEX(ArrivalDistribution[Inter-Arrival Time], MATCH(ArrivalAssignment[[#This Row],[RandomDigit]], ArrivalDistribution[Random Digit FROM], 1)) -> 3 | I29: 5 | J29: =RANDBETWEEN($K$13,$L$18) -> 55 | K29: =INDEX(ServiceDistribution3[Service Time], MATCH(ServiceTimeAssignment[[#This Row],[RandomDigit]], ServiceDistribution3[Random Digit FROM], 1)) -> 3
C30: 6 | D30: =RANDBETWEEN($E$13,$F$20) -> 338 | E30: =INDEX(ArrivalDistribution[Inter-Arrival Time], MATCH(ArrivalAssignment[[#This Row],[RandomDigit]], ArrivalDistribution[Random Digit FROM], 1)) -> 3 | I30: 6 | J30: =RANDBETWEEN($K$13,$L$18) -> 1 | K30: =INDEX(ServiceDistribution3[Service Time], MATCH(ServiceTimeAssignment[[#This Row],[RandomDigit]], ServiceDistribution3[Random Digit FROM], 1)) -> 1
C34: Simulation Table
B35: Customer | C35: IAT | D35: Arrival Time | E35: ServiceTime | F35: Service Time Start | G35: Waiting Time | H35: Service Time End | I35: Time In System | J35: Server Idle Time
B36: 1 | C36: 0 | D36: 0 | E36: =INDEX(ServiceTimeAssignment[Selected Service Time], MATCH(SimulationTable[[#This Row],[Customer]], ServiceTimeAssignment[Customer],0)) -> 3 | F36: 0 | G36: =(SimulationTable[[#This Row],[Service Time Start]]-SimulationTable[[#This Row],[Arrival Time]]) -> 0 | H36: =(SimulationTable[[#This Row],[Service Time Start]]+SimulationTable[[#This Row],[ServiceTime]]) -> 3 | I36: =(SimulationTable[[#This Row],[ServiceTime]]+SimulationTable[[#This Row],[Waiting Time]]) -> 3 | J36: 0
B37: 2 | C37: =INDEX(ArrivalAssignment[Selected Arrival Time], MATCH(SimulationTable[[#This Row],[Customer]], ArrivalAssignment[Customer],0)) -> 6 | D37: =(SimulationTable[[#This Row],[IAT]]+D36) -> 6 | E37: =INDEX(ServiceTimeAssignment[Selected Service Time], MATCH(SimulationTable[[#This Row],[Customer]], ServiceTimeAssignment[Customer],0)) -> 3 | F37: =MAX(SimulationTable[[#This Row],[Arrival Time]],H36) -> 6 | G37: =(SimulationTable[[#This Row],[Service Time Start]]-SimulationTable[[#This Row],[Arrival Time]]) -> 0 | H37: =(SimulationTable[[#This Row],[Service Time Start]]+SimulationTable[[#This Row],[ServiceTime]]) -> 9 | I37: =(SimulationTable[[#This Row],[ServiceTime]]+SimulationTable[[#This Row],[Waiting Time]]) -> 3 | J37: =(SimulationTable[[#This Row],[Service Time Start]]-H36) -> 3
B38: 3 | C38: =INDEX(ArrivalAssignment[Selected Arrival Time], MATCH(SimulationTable[[#This Row],[Customer]], ArrivalAssignment[Customer],0)) -> 4 | D38: =(SimulationTable[[#This Row],[IAT]]+D37) -> 10 | E38: =INDEX(ServiceTimeAssignment[Selected Service Time], MATCH(SimulationTable[[#This Row],[Customer]], ServiceTimeAssignment[Customer],0)) -> 2 | F38: =MAX(SimulationTable[[#This Row],[Arrival Time]],H37) -> 10 | G38: =(SimulationTable[[#This Row],[Service Time Start]]-SimulationTable[[#This Row],[Arrival Time]]) -> 0 | H38: =(SimulationTable[[#This Row],[Service Time Start]]+SimulationTable[[#This Row],[ServiceTime]]) -> 12 | I38: =(SimulationTable[[#This Row],[ServiceTime]]+SimulationTable[[#This Row],[Waiting Time]]) -> 2 | J38: =(SimulationTable[[#This Row],[Service Time Start]]-H37) -> 1
B39: 4 | C39: =INDEX(ArrivalAssignment[Selected Arrival Time], MATCH(SimulationTable[[#This Row],[Customer]], ArrivalAssignment[Customer],0)) -> 4 | D39: =(SimulationTable[[#This Row],[IAT]]+D38) -> 14 | E39: =INDEX(ServiceTimeAssignment[Selected Service Time], MATCH(SimulationTable[[#This Row],[Customer]], ServiceTimeAssignment[Customer],0)) -> 3 | F39: =MAX(SimulationTable[[#This Row],[Arrival Time]],H38) -> 14 | G39: =(SimulationTable[[#This Row],[Service Time Start]]-SimulationTable[[#This Row],[Arrival Time]]) -> 0 | H39: =(SimulationTable[[#This Row],[Service Time Start]]+SimulationTable[[#This Row],[ServiceTime]]) -> 17 | I39: =(SimulationTable[[#This Row],[ServiceTime]]+SimulationTable[[#This Row],[Waiting Time]]) -> 3 | J39: =(SimulationTable[[#This Row],[Service Time Start]]-H38) -> 2
B40: 5 | C40: =INDEX(ArrivalAssignment[Selected Arrival Time], MATCH(SimulationTable[[#This Row],[Customer]], ArrivalAssignment[Customer],0)) -> 3 | D40: =(SimulationTable[[#This Row],[IAT]]+D39) -> 17 | E40: =INDEX(ServiceTimeAssignment[Selected Service Time], MATCH(SimulationTable[[#This Row],[Customer]], ServiceTimeAssignment[Customer],0)) -> 3 | F40: =MAX(SimulationTable[[#This Row],[Arrival Time]],H39) -> 17 | G40: =(SimulationTable[[#This Row],[Service Time Start]]-SimulationTable[[#This Row],[Arrival Time]]) -> 0 | H40: =(SimulationTable[[#This Row],[Service Time Start]]+SimulationTable[[#This Row],[ServiceTime]]) -> 20 | I40: =(SimulationTable[[#This Row],[ServiceTime]]+SimulationTable[[#This Row],[Waiting Time]]) -> 3 | J40: =(SimulationTable[[#This Row],[Service Time Start]]-H39) -> 0
B41: 6 | C41: =INDEX(ArrivalAssignment[Selected Arrival Time], MATCH(SimulationTable[[#This Row],[Customer]], ArrivalAssignment[Customer],0)) -> 3 | D41: =(SimulationTable[[#This Row],[IAT]]+D40) -> 20 | E41: =INDEX(ServiceTimeAssignment[Selected Service Time], MATCH(SimulationTable[[#This Row],[Customer]], ServiceTimeAssignment[Customer],0)) -> 1 | F41: =MAX(SimulationTable[[#This Row],[Arrival Time]],H40) -> 20 | G41: =(SimulationTable[[#This Row],[Service Time Start]]-SimulationTable[[#This Row],[Arrival Time]]) -> 0 | H41: =(SimulationTable[[#This Row],[Service Time Start]]+SimulationTable[[#This Row],[ServiceTime]]) -> 21 | I41: =(SimulationTable[[#This Row],[ServiceTime]]+SimulationTable[[#This Row],[Waiting Time]]) -> 1 | J41: =(SimulationTable[[#This Row],[Service Time Start]]-H40) -> 0
B42: Total | C42: =SUBTOTAL(9, SimulationTable[IAT]) -> 20 | D42: =SUBTOTAL(9, SimulationTable[Arrival Time]) -> 67 | E42: =SUBTOTAL(9, SimulationTable[ServiceTime]) -> 15 | G42: =SUBTOTAL(9, SimulationTable[Waiting Time]) -> 0 | I42: =SUBTOTAL(9, SimulationTable[Time In System]) -> 15 | J42: =SUBTOTAL(9, SimulationTable[Server Idle Time]) -> 6
B46: Average Waiting Time of a Customer = | E46: Total Time In Queue/ Total No. of Customer
D47: = | E47: =(SimulationTable[[#Totals],[Waiting Time]] / COUNT(SimulationTable[Customer]) ) -> 0
B50: Probability(CustomerInQueue) = | E50: No. of Customer In Queue/ Total No. of Customer
D51: = | E51: =(COUNTIF(SimulationTable[Waiting Time], ">0") / COUNT(SimulationTable[Customer]) ) -> 0
B53: Probability(ServerIdle) = | E53: Total Idle Server Time/ Last Service Time End
D54: = | E54: =(SimulationTable[[#Totals],[Server Idle Time]] / $H$41 ) -> 0.28571429
B56: Avg Service Time = | E56: Total Service Time / Total No. of Customer
...

Sheet Q6-MonteCarloSim
B1: Monte-Carlo Simulation for value of PI
C3: Rectangular Points | F3: Points In Circle
C4: X | D4: Y | E4: InCircle? | F4: X | G4: Y
B5: Points | C5: =_xlfn.FORMULATEXT(C6) -> =1-2*RAND() | D5: =_xlfn.FORMULATEXT(D6) -> =1-2*RAND() | E5: =_xlfn.FORMULATEXT(E6) -> =IF(C6^2+D6^2<1, 1, 0) | F5: =_xlfn.FORMULATEXT(F6) -> =IF((C6^2+D6^2)<1, C6, 0) | G5: =_xlfn.FORMULATEXT(G6) -> =IF((C6^2+D6^2)<1, D6, 0)
B6: 1 | C6: =1-2*RAND() -> 0.11852849 | D6: =1-2*RAND() -> 0.89283156 | E6: =IF(C6^2+D6^2<1, 1, 0) -> 1 | F6: =IF((C6^2+D6^2)<1, C6, 0) -> 0.11852849 | G6: =IF((C6^2+D6^2)<1, D6, 0) -> 0.89283156
B7: 2 | C7: =1-2*RAND() -> -0.87189426 | D7: =1-2*RAND() -> -0.65248758 | E7: =IF(C7^2+D7^2<1, 1, 0) -> 0 | F7: =IF((C7^2+D7^2)<1, C7, 0) -> 0 | G7: =IF((C7^2+D7^2)<1, D7, 0) -> 0
B8: 3 | C8: =1-2*RAND() -> -0.17582816 | D8: =1-2*RAND() -> -0.39865784 | E8: =IF(C8^2+D8^2<1, 1, 0) -> 1 | F8: =IF((C8^2+D8^2)<1, C8, 0) -> -0.17582816 | G8: =IF((C8^2+D8^2)<1, D8, 0) -> -0.39865784 | J8: Total Points inside circle | M8: =COUNTIF(E6:E1005, "=1") -> 795 | N8: =_xlfn.FORMULATEXT(M8) -> =COUNTIF(E6:E1005, "=1")
B9: 4 | C9: =1-2*RAND() -> 0.44938386 | D9: =1-2*RAND() -> 0.97347074 | E9: =IF(C9^2+D9^2<1, 1, 0) -> 0 | F9: =IF((C9^2+D9^2)<1, C9, 0) -> 0 | G9: =IF((C9^2+D9^2)<1, D9, 0) -> 0 | J9: Total number of Sample Points | M9: =COUNT(E6:E1005) -> 1000 | N9: =_xlfn.FORMULATEXT(M9) -> =COUNT(E6:E1005)
B10: 5 | C10: =1-2*RAND() -> 0.16618365 | D10: =1-2*RAND() -> -0.20168179 | E10: =IF(C10^2+D10^2<1, 1, 0) -> 1 | F10: =IF((C10^2+D10^2)<1, C10, 0) -> 0.16618365 | G10: =IF((C10^2+D10^2)<1, D10, 0) -> -0.20168179 | J10: n/N | M10: =M8/M9 -> 0.795 | N10: =_xlfn.FORMULATEXT(M10) -> =M8/M9
B11: 6 | C11: =1-2*RAND() -> 0.80136571 | D11: =1-2*RAND() -> 0.17875742 | E11: =IF(C11^2+D11^2<1, 1, 0) -> 1 | F11: =IF((C11^2+D11^2)<1, C11, 0) -> 0.80136571 | G11: =IF((C11^2+D11^2)<1, D11, 0) -> 0.17875742 | J11: Value of PI | M11: =M10*4 -> 3.18 | N11: =_xlfn.FORMULATEXT(M11) -> =M10*4
B12: 7 | C12: =1-2*RAND() -> 0.83459978 | D12: =1-2*RAND() -> 0.1256824 | E12: =IF(C12^2+D12^2<1, 1, 0) -> 1 | F12: =IF((C12^2+D12^2)<1, C12, 0) -> 0.83459978 | G12: =IF((C12^2+D12^2)<1, D12, 0) -> 0.1256824
B13: 8 | C13: =1-2*RAND() -> 0.78412472 | D13: =1-2*RAND() -> 0.029315799 | E13: =IF(C13^2+D13^2<1, 1, 0) -> 1 | F13: =IF((C13^2+D13^2)<1, C13, 0) -> 0.78412472 | G13: =IF((C13^2+D13^2)<1, D13, 0) -> 0.029315799
B14: 9 | C14: =1-2*RAND() -> -0.84754634 | D14: =1-2*RAND() -> 0.49279297 | E14: =IF(C14^2+D14^2<1, 1, 0) -> 1 | F14: =IF((C14^2+D14^2)<1, C14, 0) -> -0.84754634 | G14: =IF((C14^2+D14^2)<1, D14, 0) -> 0.49279297
B15: 10 | C15: =1-2*RAND() -> -0.72366605 | D15: =1-2*RAND() -> 0.72677774 | E15: =IF(C15^2+D15^2<1, 1, 0) -> 0 | F15: =IF((C15^2+D15^2)<1, C15, 0) -> 0 | G15: =IF((C15^2+D15^2)<1, D15, 0) -> 0
B16: 11 | C16: =1-2*RAND() -> -0.80844294 | D16: =1-2*RAND() -> -0.021965918 | E16: =IF(C16^2+D16^2<1, 1, 0) -> 1 | F16: =IF((C16^2+D16^2)<1, C16, 0) -> -0.80844294 | G16: =IF((C16^2+D16^2)<1, D16, 0) -> -0.021965918
B17: 12 | C17: =1-2*RAND() -> -0.88334916 | D17: =1-2*RAND() -> 0.028414233 | E17: =IF(C17^2+D17^2<1, 1, 0) -> 1 | F17: =IF((C17^2+D17^2)<1, C17, 0) -> -0.88334916 | G17: =IF((C17^2+D17^2)<1, D17, 0) -> 0.028414233
B18: 13 | C18: =1-2*RAND() -> 0.41858738 | D18: =1-2*RAND() -> 0.78172729 | E18: =IF(C18^2+D18^2<1, 1, 0) -> 1 | F18: =IF((C18^2+D18^2)<1, C18, 0) -> 0.41858738 | G18: =IF((C18^2+D18^2)<1, D18, 0) -> 0.78172729
B19: 14 | C19: =1-2*RAND() -> 0.69179474 | D19: =1-2*RAND() -> -0.9037447 | E19: =IF(C19^2+D19^2<1, 1, 0) -> 0 | F19: =IF((C19^2+D19^2)<1, C19, 0) -> 0 | G19: =IF((C19^2+D19^2)<1, D19, 0) -> 0
B20: 15 | C20: =1-2*RAND() -> -0.092915382 | D20: =1-2*RAND() -> -0.5884796 | E20: =IF(C20^2+D20^2<1, 1, 0) -> 1 | F20: =IF((C20^2+D20^2)<1, C20, 0) -> -0.092915382 | G20: =IF((C20^2+D20^2)<1, D20, 0) -> -0.5884796
B21: 16 | C21: =1-2*RAND() -> 0.17146841 | D21: =1-2*RAND() -> -0.00062772779 | E21: =IF(C21^2+D21^2<1, 1, 0) -> 1 | F21: =IF((C21^2+D21^2)<1, C21, 0) -> 0.17146841 | G21: =IF((C21^2+D21^2)<1, D21, 0) -> -0.00062772779
B22: 17 | C22: =1-2*RAND() -> 0.96631732 | D22: =1-2*RAND() -> -0.56745815 | E22: =IF(C22^2+D22^2<1, 1, 0) -> 0 | F22: =IF((C22^2+D22^2)<1, C22, 0) -> 0 | G22: =IF((C22^2+D22^2)<1, D22, 0) -> 0
B23: 18 | C23: =1-2*RAND() -> -0.91005401 | D23: =1-2*RAND() -> 0.78973478 | E23: =IF(C23^2+D23^2<1, 1, 0) -> 0 | F23: =IF((C23^2+D23^2)<1, C23, 0) -> 0 | G23: =IF((C23^2+D23^2)<1, D23, 0) -> 0
... B1005: 1000 | C1005: =1-2*RAND() -> -0.21279758 | D1005: =1-2*RAND() -> 0.88573468 | E1005: =IF(C1005^2+D1005^2<1, 1, 0) -> 1 | F1005: =IF((C1005^2+D1005^2)<1, C1005, 0) -> -0.21279758 | G1005: =IF((C1005^2+D1005^2)<1, D1005, 0) -> 0.88573468

Sheet Q7-ChiSquareTest
V1: Num | W1: DataSet
B2: Perform Uniformity test using Chi-square test. | V2: 1 | W2: =RAND() -> 0.24492056
V3: 2 | W3: =RAND() -> 0.94854654
B4: Constructing data set using RAND() for 690 samples | V4: 3 | W4: =RAND() -> 0.8159456
V5: 4 | W5: =RAND() -> 0.58402947
B6: Total Samples | D6: =COUNT(V2:V691) -> 690 | V6: 5 | W6: =RAND() -> 0.37906344
B7: Min Value | D7: =MIN(W2:W691) -> 0.00019979277 | V7: 6 | W7: =RAND() -> 0.40521523
B8: Max Value | D8: =MAX(W2:W692) -> 0.99967219 | V8: 7 | W8: =RAND() -> 0.93351105
B9: Constructing n = 10 intervals of equal width; | V9: 8 | W9: =RAND() -> 0.62107204
B10: i.e | V10: 9 | W10: =RAND() -> 0.59360575
B11: Number of Class | D11: 10 | V11: 10 | W11: =RAND() -> 0.85591283
B12: Expected Frequency | D12: =D6/D11 -> 69 | E12: TotalSample/No. Of Class | V12: 11 | W12: =RAND() -> 0.95871361
V13: 12 | W13: =RAND() -> 0.56889598
B14: SN | C14: ClassInterval(From) | D14: ClassInterval(To) | E14: Observed Frequency(Oi) | F14: Expected Frequency(Ei) | G14: (Oi - Ei)²/ Ei | V14: 13 | W14: =RAND() -> 0.37411993
B15: 1 | C15: 0 | D15: ='Q7-ChiSquareTest'!$C15+0.1 -> 0.1 | E15: {=FREQUENCY(W2:W692, 'Q7-ChiSquareTest'!$D$15:$D$24)} -> 68 | F15: =$D$12 -> 69 | G15: =('Q7-ChiSquareTest'!$E15-'Q7-ChiSquareTest'!$F15)^2/'Q7-ChiSquareTest'!$F15 -> 0.014492754 | V15: 14 | W15: =RAND() -> 0.93430974
B16: 2 | C16: =D15 -> 0.1 | D16: ='Q7-ChiSquareTest'!$C16+0.1 -> 0.2 | E16: 85 | F16: =$D$12 -> 69 | G16: =('Q7-ChiSquareTest'!$E16-'Q7-ChiSquareTest'!$F16)^2/'Q7-ChiSquareTest'!$F16 -> 3.7101449 | V16: 15 | W16: =RAND() -> 0.59484161
B17: 3 | C17: =D16 -> 0.2 | D17: ='Q7-ChiSquareTest'!$C17+0.1 -> 0.3 | E17: 79 | F17: =$D$12 -> 69 | G17: =('Q7-ChiSquareTest'!$E17-'Q7-ChiSquareTest'!$F17)^2/'Q7-ChiSquareTest'!$F17 -> 1.4492754 | V17: 16 | W17: =RAND() -> 0.41019303
B18: 4 | C18: =D17 -> 0.3 | D18: ='Q7-ChiSquareTest'!$C18+0.1 -> 0.4 | E18: 65 | F18: =$D$12 -> 69 | G18: =('Q7-ChiSquareTest'!$E18-'Q7-ChiSquareTest'!$F18)^2/'Q7-ChiSquareTest'!$F18 -> 0.23188406 | V18: 17 | W18: =RAND() -> 0.13103615
B19: 5 | C19: =D18 -> 0.4 | D19: ='Q7-ChiSquareTest'!$C19+0.1 -> 0.5 | E19: 73 | F19: =$D$12 -> 69 | G19: =('Q7-ChiSquareTest'!$E19-'Q7-ChiSquareTest'!$F19)^2/'Q7-ChiSquareTest'!$F19 -> 0.23188406 | V19: 18 | W19: =RAND() -> 0.026307153
B20: 6 | C20: =D19 -> 0.5 | D20: ='Q7-ChiSquareTest'!$C20+0.1 -> 0.6 | E20: 68 | F20: =$D$12 -> 69 | G20: =('Q7-ChiSquareTest'!$E20-'Q7-ChiSquareTest'!$F20)^2/'Q7-ChiSquareTest'!$F20 -> 0.014492754 | V20: 19 | W20: =RAND() -> 0.22528099
B21: 7 | C21: =D20 -> 0.6 | D21: ='Q7-ChiSquareTest'!$C21+0.1 -> 0.7 | E21: 63 | F21: =$D$12 -> 69 | G21: =('Q7-ChiSquareTest'!$E21-'Q7-ChiSquareTest'!$F21)^2/'Q7-ChiSquareTest'!$F21 -> 0.52173913 | V21: 20 | W21: =RAND() -> 0.35639861
B22: 8 | C22: =D21 -> 0.7 | D22: ='Q7-ChiSquareTest'!$C22+0.1 -> 0.8 | E22: 59 | F22: =$D$12 -> 69 | G22: =('Q7-ChiSquareTest'!$E22-'Q7-ChiSquareTest'!$F22)^2/'Q7-ChiSquareTest'!$F22 -> 1.4492754 | V22: 21 | W22: =RAND() -> 0.019850077
B23: 9 | C23: =D22 -> 0.8 | D23: ='Q7-ChiSquareTest'!$C23+0.1 -> 0.9 | E23: 56 | F23: =$D$12 -> 69 | G23: =('Q7-ChiSquareTest'!$E23-'Q7-ChiSquareTest'!$F23)^2/'Q7-ChiSquareTest'!$F23 -> 2.4492754 | V23: 22 | W23: =RAND() -> 0.18728795
B24: 10 | C24: =D23 -> 0.9 | D24: ='Q7-ChiSquareTest'!$C24+0.1 -> 1 | E24: 74 | F24: =$D$12 -> 69 | G24: =('Q7-ChiSquareTest'!$E24-'Q7-ChiSquareTest'!$F24)^2/'Q7-ChiSquareTest'!$F24 -> 0.36231884 | V24: 23 | W24: =RAND() -> 0.55678929
B25: Total | E25: =SUBTOTAL(9,'Q7-ChiSquareTest'!$E$15:$E$24) -> 690 | F25: =SUBTOTAL(9, 'Q7-ChiSquareTest'!$F$15:$F$24) -> 690 | G25: =SUBTOTAL(9, $G$15:$G$24) -> 10.434783 | V25: 24 | W25: =RAND() -> 0.52650078
V26: 25 | W26: =RAND() -> 0.073023937
V27: 26 | W27: =RAND() -> 0.51054169
B28: Here | V28: 27 | W28: =RAND() -> 0.67601514
B29: Calculated χ² | D29: =G25 -> 10.434783 | E29: Σ(Oi - Ei)²/ Ei | V29: 28 | W29: =RAND() -> 0.54459189
B30: Degree of Freedom | D30: =D11-1 -> 9 | E30: = n - 1 | V30: 29 | W30: =RAND() -> 0.62292262
B31: Level of Significance | D31: 0.05 | V31: 30 | W31: =RAND() -> 0.84872879
B32: Critical Value | D32: =CHIINV(D31, D30) -> 16.918978 | E32: =_xlfn.FORMULATEXT(D32) -> =CHIINV(D31, D30) | V32: 31 | W32: =RAND() -> 0.21123585
V33: 32 | W33: =RAND() -> 0.29882796
B34: Conclusion | V34: 33 | W34: =RAND() -> 0.0065236728
B35: =_xlfn.TEXTJOIN(, FALSE, IF(D29<D32, _xlfn.TEXTJOIN(,FALSE, _xlfn.VALUETOTEXT(B29), " < ", _xlfn.VALUETOTEXT(B32)), _xlfn.TEXTJOIN(,FALSE, _xlfn.VALUETOTEXT(B29), " >= ", _xlfn.VALUETOTEXT(B32)))) -> Calculated χ² < Critical Value | V35: 34 | W35: =RAND() -> 0.57614154
V36: 35 | W36: =RAND() -> 0.75247122
V37: 36 | W37: =RAND() -> 0.17181429
V38: 37 | W38: =RAND() -> 0.92218529
V39: 38 | W39: =RAND() -> 0.77052948
V40: 39 | W40: =RAND() -> 0.76435533
...
